Workbook
Name BillingsThreshold_North: 'KPI Dashboard North'!$Q$17:$U$20
Name BillingsThreshold_OT: 'KPI Dashboard OT'!$Q$15:$U$18
Name BillingsThreshold_South: 'KPI Dashboard South'!$Q$15:$U$18
Name CeasedThreshold_North: 'KPI Dashboard North'!$Q$26:$U$28
Name CeasedThreshold_South: 'KPI Dashboard South'!$Q$24:$U$26
Name MMP_KPI: 'MMP Dashboard'!$C$32:$H$36
Name TeamKPI_North: 'KPI Dashboard North'!$Q$7:$W$12
Name TeamKPI_OT: 'KPI Dashboard OT'!$Q$7:$W$10
Name TeamKPI_South: 'KPI Dashboard South'!$Q$7:$W$10

Sheet MMP Dashboard
A2: #VALUE! | C2: Melbourne Mobile Physio
A10: South | C10: Team Average | D10: Jan | E10: Feb | F10: Mar | G10: Apr | H10: May | I10: June | J10: July | K10: Aug | L10: Sept | M10: Oct | N10: Nov | O10: Dec | P10: Average
C11: Billings | D11: =IF(SUMIFS(FTETable[Jan], FTETable[Team], "Physio_South")=0, "", SUMIFS(FTETable[Jan], FTETable[Team], "Physio_South") / SUMIFS(FTETable[FTE], FTETable[Team], "Physio_South", FTETable[Jan], ">0")) | E11: =IF(SUMIFS(FTETable[Feb], FTETable[Team], "Physio_South")=0, "", SUMIFS(FTETable[Feb], FTETable[Team], "Physio_South") / SUMIFS(FTETable[FTE], FTETable[Team], "Physio_South", FTETable[Feb], ">0")) | F11: =IF(SUMIFS(FTETable[Mar], FTETable[Team], "Physio_South")=0, "", SUMIFS(FTETable[Mar], FTETable[Team], "Physio_South") / SUMIFS(FTETable[FTE], FTETable[Team], "Physio_South", FTETable[Mar], ">0")) | G11: =IF(SUMIFS(FTETable[Apr], FTETable[Team], "Physio_South")=0, "", SUMIFS(FTETable[Apr], FTETable[Team], "Physio_South") / SUMIFS(FTETable[FTE], FTETable[Team], "Physio_South", FTETable[Apr], ">0")) | H11: =IF(SUMIFS(FTETable[May], FTETable[Team], "Physio_South")=0, "", SUMIFS(FTETable[May], FTETable[Team], "Physio_South") / SUMIFS(FTETable[FTE], FTETable[Team], "Physio_South", FTETable[May], ">0")) | I11: =IF(SUMIFS(FTETable[June], FTETable[Team], "Physio_South")=0, "", SUMIFS(FTETable[June], FTETable[Team], "Physio_South") / SUMIFS(FTETable[FTE], FTETable[Team], "Physio_South", FTETable[June], ">0")) | J11: =IF(SUMIFS(FTETable[July], FTETable[Team], "Physio_South")=0, "", SUMIFS(FTETable[July], FTETable[Team], "Physio_South") / SUMIFS(FTETable[FTE], FTETable[Team], "Physio_South", FTETable[July], ">0")) | K11: =IF(SUMIFS(FTETable[Aug], FTETable[Team], "Physio_South")=0, "", SUMIFS(FTETable[Aug], FTETable[Team], "Physio_South") / SUMIFS(FTETable[FTE], FTETable[Team], "Physio_South", FTETable[Aug], ">0")) | L11: =IF(SUMIFS(FTETable[Sept], FTETable[Team], "Physio_South")=0, "", SUMIFS(FTETable[Sept], FTETable[Team], "Physio_South") / SUMIFS(FTETable[FTE], FTETable[Team], "Physio_South", FTETable[Sept], ">0")) | M11: =IF(SUMIFS(FTETable[Oct], FTETable[Team], "Physio_South")=0, "", SUMIFS(FTETable[Oct], FTETable[Team], "Physio_South") / SUMIFS(FTETable[FTE], FTETable[Team], "Physio_South", FTETable[Oct], ">0")) | N11: =IF(SUMIFS(FTETable[Nov], FTETable[Team], "Physio_South")=0, "", SUMIFS(FTETable[Nov], FTETable[Team], "Physio_South") / SUMIFS(FTETable[FTE], FTETable[Team], "Physio_South", FTETable[Nov], ">0")) | O11: =IF(SUMIFS(FTETable[Dec], FTETable[Team], "Physio_South")=0, "", SUMIFS(FTETable[Dec], FTETable[Team], "Physio_South") / SUMIFS(FTETable[FTE], FTETable[Team], "Physio_South", FTETable[Dec], ">0")) | P11: =IFERROR(AVERAGEIF(D11:O11, ">0"),"")
C12: Ceased Services | D12: =IFERROR(AVERAGE(Ceased_South[Jan]),"") | E12: =IFERROR(AVERAGE(Ceased_South[Feb]),"") | F12: =IFERROR(AVERAGE(Ceased_South[Mar]),"") | G12: =IFERROR(AVERAGE(Ceased_South[Apr]),"") | H12: =IFERROR(AVERAGE(Ceased_South[May]),"") | I12: =IFERROR(AVERAGE(Ceased_South[June]),"") | J12: =IFERROR(AVERAGE(Ceased_South[July]),"") | K12: =IFERROR(AVERAGE(Ceased_South[Aug]),"") | L12: =IFERROR(AVERAGE(Ceased_South[Sept]),"") | M12: =IFERROR(AVERAGE(Ceased_South[Oct]),"") | N12: =IFERROR(AVERAGE(Ceased_South[Nov]),"") | O12: =IFERROR(AVERAGE(Ceased_South[Dec]),"") | P12: =IFERROR(AVERAGEIF(D12:O12, ">0"),"")
C13: Documentation | D13: =IFERROR(AVERAGE(Documentation_South[Jan]),"") | E13: =IFERROR(AVERAGE(Documentation_South[Feb]),"") | F13: =IFERROR(AVERAGE(Documentation_South[Mar]),"") | G13: =IFERROR(AVERAGE(Documentation_South[Apr]),"") | H13: =IFERROR(AVERAGE(Documentation_South[May]),"") | I13: =IFERROR(AVERAGE(Documentation_South[June]),"") | J13: =IFERROR(AVERAGE(Documentation_South[July]),"") | K13: =IFERROR(AVERAGE(Documentation_South[Aug]),"") | L13: =IFERROR(AVERAGE(Documentation_South[Sept]),"") | M13: =IFERROR(AVERAGE(Documentation_South[Oct]),"") | N13: =IFERROR(AVERAGE(Documentation_South[Nov]),"") | O13: =IFERROR(AVERAGE(Documentation_South[Dec]),"") | P13: =IFERROR(AVERAGEIF(D13:O13, ">0"),"")
C14: Admin & Operational Efficiency | D14: =IFERROR(AVERAGE(Admin_South[Jan]),"") | E14: =IFERROR(AVERAGE(Admin_South[Feb]),"") | F14: =IFERROR(AVERAGE(Admin_South[Mar]),"") | G14: =IFERROR(AVERAGE(Admin_South[Apr]),"") | H14: =IFERROR(AVERAGE(Admin_South[May]),"") | I14: =IFERROR(AVERAGE(Admin_South[June]),"") | J14: =IFERROR(AVERAGE(Admin_South[July]),"") | K14: =IFERROR(AVERAGE(Admin_South[Aug]),"") | L14: =IFERROR(AVERAGE(Admin_South[Sept]),"") | M14: =IFERROR(AVERAGE(Admin_South[Oct]),"") | N14: =IFERROR(AVERAGE(Admin_South[Nov]),"") | O14: =IFERROR(AVERAGE(Admin_South[Dec]),"") | P14: =IFERROR(AVERAGEIF(D14:O14, ">0"),"")
C15: Attitude, Learning, Collaboration & Client Impact | D15: =IFERROR(AVERAGE(Attitude_South[Jan]),"") | E15: =IFERROR(AVERAGE(Attitude_South[Feb]),"") | F15: =IFERROR(AVERAGE(Attitude_South[Mar]),"") | G15: =IFERROR(AVERAGE(Attitude_South[Apr]),"") | H15: =IFERROR(AVERAGE(Attitude_South[May]),"") | I15: =IFERROR(AVERAGE(Attitude_South[June]),"") | J15: =IFERROR(AVERAGE(Attitude_South[July]),"") | K15: =IFERROR(AVERAGE(Attitude_South[Aug]),"") | L15: =IFERROR(AVERAGE(Attitude_South[Sept]),"") | M15: =IFERROR(AVERAGE(Attitude_South[Oct]),"") | N15: =IFERROR(AVERAGE(Attitude_South[Nov]),"") | O15: =IFERROR(AVERAGE(Attitude_South[Dec]),"") | P15: =IFERROR(AVERAGEIF(D15:O15, ">0"),"")
A17: North | C17: Team Average | D17: Jan | E17: Feb | F17: Mar | G17: Apr | H17: May | I17: June | J17: July | K17: Aug | L17: Sept | M17: Oct | N17: Nov | O17: Dec | P17: Average
C18: Billings | D18: =IF(SUMIFS(FTETable[Jan], FTETable[Team], "Physio_North")=0, "", SUMIFS(FTETable[Jan], FTETable[Team], "Physio_North") / SUMIFS(FTETable[FTE], FTETable[Team], "Physio_North", FTETable[Jan], ">0")) | E18: =IF(SUMIFS(FTETable[Feb], FTETable[Team], "Physio_North")=0, "", SUMIFS(FTETable[Feb], FTETable[Team], "Physio_North") / SUMIFS(FTETable[FTE], FTETable[Team], "Physio_North", FTETable[Feb], ">0")) | F18: =IF(SUMIFS(FTETable[Mar], FTETable[Team], "Physio_North")=0, "", SUMIFS(FTETable[Mar], FTETable[Team], "Physio_North") / SUMIFS(FTETable[FTE], FTETable[Team], "Physio_North", FTETable[Mar], ">0")) | G18: =IF(SUMIFS(FTETable[Apr], FTETable[Team], "Physio_North")=0, "", SUMIFS(FTETable[Apr], FTETable[Team], "Physio_North") / SUMIFS(FTETable[FTE], FTETable[Team], "Physio_North", FTETable[Apr], ">0")) | H18: =IF(SUMIFS(FTETable[May], FTETable[Team], "Physio_North")=0, "", SUMIFS(FTETable[May], FTETable[Team], "Physio_North") / SUMIFS(FTETable[FTE], FTETable[Team], "Physio_North", FTETable[May], ">0")) | I18: =IF(SUMIFS(FTETable[June], FTETable[Team], "Physio_North")=0, "", SUMIFS(FTETable[June], FTETable[Team], "Physio_North") / SUMIFS(FTETable[FTE], FTETable[Team], "Physio_North", FTETable[June], ">0")) | J18: =IF(SUMIFS(FTETable[July], FTETable[Team], "Physio_North")=0, "", SUMIFS(FTETable[July], FTETable[Team], "Physio_North") / SUMIFS(FTETable[FTE], FTETable[Team], "Physio_North", FTETable[July], ">0")) | K18: =IF(SUMIFS(FTETable[Aug], FTETable[Team], "Physio_North")=0, "", SUMIFS(FTETable[Aug], FTETable[Team], "Physio_North") / SUMIFS(FTETable[FTE], FTETable[Team], "Physio_North", FTETable[Aug], ">0")) | L18: =IF(SUMIFS(FTETable[Sept], FTETable[Team], "Physio_North")=0, "", SUMIFS(FTETable[Sept], FTETable[Team], "Physio_North") / SUMIFS(FTETable[FTE], FTETable[Team], "Physio_North", FTETable[Sept], ">0")) | M18: =IF(SUMIFS(FTETable[Oct], FTETable[Team], "Physio_North")=0, "", SUMIFS(FTETable[Oct], FTETable[Team], "Physio_North") / SUMIFS(FTETable[FTE], FTETable[Team], "Physio_North", FTETable[Oct], ">0")) | N18: =IF(SUMIFS(FTETable[Nov], FTETable[Team], "Physio_North")=0, "", SUMIFS(FTETable[Nov], FTETable[Team], "Physio_North") / SUMIFS(FTETable[FTE], FTETable[Team], "Physio_North", FTETable[Nov], ">0")) | O18: =IF(SUMIFS(FTETable[Dec], FTETable[Team], "Physio_North")=0, "", SUMIFS(FTETable[Dec], FTETable[Team], "Physio_North") / SUMIFS(FTETable[FTE], FTETable[Team], "Physio_North", FTETable[Dec], ">0")) | P18: =IFERROR(AVERAGEIF(D18:O18, ">0"),"")
C19: Ceased Services | D19: =IFERROR(AVERAGE(Ceased_North[Jan]),"") | E19: =IFERROR(AVERAGE(Ceased_North[Feb]),"") | F19: =IFERROR(AVERAGE(Ceased_North[Mar]),"") | G19: =IFERROR(AVERAGE(Ceased_North[Apr]),"") | H19: =IFERROR(AVERAGE(Ceased_North[May]),"") | I19: =IFERROR(AVERAGE(Ceased_North[June]),"") | J19: =IFERROR(AVERAGE(Ceased_North[July]),"") | K19: =IFERROR(AVERAGE(Ceased_North[Aug]),"") | L19: =IFERROR(AVERAGE(Ceased_North[Sept]),"") | M19: =IFERROR(AVERAGE(Ceased_North[Oct]),"") | N19: =IFERROR(AVERAGE(Ceased_North[Nov]),"") | O19: =IFERROR(AVERAGE(Ceased_North[Dec]),"") | P19: =IFERROR(AVERAGEIF(D19:O19, ">0"),"")
C20: Documentation | D20: =IFERROR(AVERAGE(Documentation_North[Jan]),"") | E20: =IFERROR(AVERAGE(Documentation_North[Feb]),"") | F20: =IFERROR(AVERAGE(Documentation_North[Mar]),"") | G20: =IFERROR(AVERAGE(Documentation_North[Apr]),"") | H20: =IFERROR(AVERAGE(Documentation_North[May]),"") | I20: =IFERROR(AVERAGE(Documentation_North[June]),"") | J20: =IFERROR(AVERAGE(Documentation_North[July]),"") | K20: =IFERROR(AVERAGE(Documentation_North[Aug]),"") | L20: =IFERROR(AVERAGE(Documentation_North[Sept]),"") | M20: =IFERROR(AVERAGE(Documentation_North[Oct]),"") | N20: =IFERROR(AVERAGE(Documentation_North[Nov]),"") | O20: =IFERROR(AVERAGE(Documentation_North[Dec]),"") | P20: =IFERROR(AVERAGEIF(D20:O20, ">0"),"")
C21: Admin & Operational Efficiency | D21: =IFERROR(AVERAGE(Admin_North[Jan]),"") | E21: =IFERROR(AVERAGE(Admin_North[Feb]),"") | F21: =IFERROR(AVERAGE(Admin_North[Mar]),"") | G21: =IFERROR(AVERAGE(Admin_North[Apr]),"") | H21: =IFERROR(AVERAGE(Admin_North[May]),"") | I21: =IFERROR(AVERAGE(Admin_North[June]),"") | J21: =IFERROR(AVERAGE(Admin_North[July]),"") | K21: =IFERROR(AVERAGE(Admin_North[Aug]),"") | L21: =IFERROR(AVERAGE(Admin_North[Sept]),"") | M21: =IFERROR(AVERAGE(Admin_North[Oct]),"") | N21: =IFERROR(AVERAGE(Admin_North[Nov]),"") | O21: =IFERROR(AVERAGE(Admin_North[Dec]),"") | P21: =IFERROR(AVERAGEIF(D21:O21, ">0"),"")
C22: Attitude, Learning, Collaboration & Client Impact | D22: =IFERROR(AVERAGE(Attitude_North[Jan]),"") | E22: =IFERROR(AVERAGE(Attitude_North[Feb]),"") | F22: =IFERROR(AVERAGE(Attitude_North[Mar]),"") | G22: =IFERROR(AVERAGE(Attitude_North[Apr]),"") | H22: =IFERROR(AVERAGE(Attitude_North[May]),"") | I22: =IFERROR(AVERAGE(Attitude_North[June]),"") | J22: =IFERROR(AVERAGE(Attitude_North[July]),"") | K22: =IFERROR(AVERAGE(Attitude_North[Aug]),"") | L22: =IFERROR(AVERAGE(Attitude_North[Sept]),"") | M22: =IFERROR(AVERAGE(Attitude_North[Oct]),"") | N22: =IFERROR(AVERAGE(Attitude_North[Nov]),"") | O22: =IFERROR(AVERAGE(Attitude_North[Dec]),"") | P22: =IFERROR(AVERAGEIF(D22:O22, ">0"),"")
A24: OT | C24: Team Average | D24: Jan | E24: Feb | F24: Mar | G24: Apr | H24: May | I24: June | J24: July | K24: Aug | L24: Sept | M24: Oct | N24: Nov | O24: Dec | P24: Average
C25: Billings | D25: =IF(SUMIFS(FTETable[Jan], FTETable[Team], "OT")=0, "", SUMIFS(FTETable[Jan], FTETable[Team], "OT") / SUMIFS(FTETable[FTE], FTETable[Team], "OT", FTETable[Jan], ">0")) | E25: =IF(SUMIFS(FTETable[Feb], FTETable[Team], "OT")=0, "", SUMIFS(FTETable[Feb], FTETable[Team], "OT") / SUMIFS(FTETable[FTE], FTETable[Team], "OT", FTETable[Feb], ">0")) | F25: =IF(SUMIFS(FTETable[Mar], FTETable[Team], "OT")=0, "", SUMIFS(FTETable[Mar], FTETable[Team], "OT") / SUMIFS(FTETable[FTE], FTETable[Team], "OT", FTETable[Mar], ">0")) | G25: =IF(SUMIFS(FTETable[Apr], FTETable[Team], "OT")=0, "", SUMIFS(FTETable[Apr], FTETable[Team], "OT") / SUMIFS(FTETable[FTE], FTETable[Team], "OT", FTETable[Apr], ">0")) | H25: =IF(SUMIFS(FTETable[May], FTETable[Team], "OT")=0, "", SUMIFS(FTETable[May], FTETable[Team], "OT") / SUMIFS(FTETable[FTE], FTETable[Team], "OT", FTETable[May], ">0")) | I25: =IF(SUMIFS(FTETable[June], FTETable[Team], "OT")=0, "", SUMIFS(FTETable[June], FTETable[Team], "OT") / SUMIFS(FTETable[FTE], FTETable[Team], "OT", FTETable[June], ">0")) | J25: =IF(SUMIFS(FTETable[July], FTETable[Team], "OT")=0, "", SUMIFS(FTETable[July], FTETable[Team], "OT") / SUMIFS(FTETable[FTE], FTETable[Team], "OT", FTETable[July], ">0")) | K25: =IF(SUMIFS(FTETable[Aug], FTETable[Team], "OT")=0, "", SUMIFS(FTETable[Aug], FTETable[Team], "OT") / SUMIFS(FTETable[FTE], FTETable[Team], "OT", FTETable[Aug], ">0")) | L25: =IF(SUMIFS(FTETable[Sept], FTETable[Team], "OT")=0, "", SUMIFS(FTETable[Sept], FTETable[Team], "OT") / SUMIFS(FTETable[FTE], FTETable[Team], "OT", FTETable[Sept], ">0")) | M25: =IF(SUMIFS(FTETable[Oct], FTETable[Team], "OT")=0, "", SUMIFS(FTETable[Oct], FTETable[Team], "OT") / SUMIFS(FTETable[FTE], FTETable[Team], "OT", FTETable[Oct], ">0")) | N25: =IF(SUMIFS(FTETable[Nov], FTETable[Team], "OT")=0, "", SUMIFS(FTETable[Nov], FTETable[Team], "OT") / SUMIFS(FTETable[FTE], FTETable[Team], "OT", FTETable[Nov], ">0")) | O25: =IF(SUMIFS(FTETable[Dec], FTETable[Team], "OT")=0, "", SUMIFS(FTETable[Dec], FTETable[Team], "OT") / SUMIFS(FTETable[FTE], FTETable[Team], "OT", FTETable[Dec], ">0")) | P25: =IFERROR(AVERAGEIF(D25:O25, ">0"),"")
C26: Operational Efficiency, Compliance & Admin Responsiveness | D26: =IFERROR(AVERAGE(Compliance_OT[Jan]),"") | E26: =IFERROR(AVERAGE(Compliance_OT[Feb]),"") | F26: =IFERROR(AVERAGE(Compliance_OT[Mar]),"") | G26: =IFERROR(AVERAGE(Compliance_OT[Apr]),"") | H26: =IFERROR(AVERAGE(Compliance_OT[May]),"") | I26: =IFERROR(AVERAGE(Compliance_OT[June]),"") | J26: =IFERROR(AVERAGE(Compliance_OT[July]),"") | K26: =IFERROR(AVERAGE(Compliance_OT[Aug]),"") | L26: =IFERROR(AVERAGE(Compliance_OT[Sept]),"") | M26: =IFERROR(AVERAGE(Compliance_OT[Oct]),"") | N26: =IFERROR(AVERAGE(Compliance_OT[Nov]),"") | O26: =IFERROR(AVERAGE(Compliance_OT[Dec]),"") | P26: =IFERROR(AVERAGEIF(D26:O26, ">0"),"")
C27: Client & Referrer Satisfaction | D27: =IFERROR(AVERAGE(ReferrerEng_OT[Jan]),"") | E27: =IFERROR(AVERAGE(ReferrerEng_OT[Feb]),"") | F27: =IFERROR(AVERAGE(ReferrerEng_OT[Mar]),"") | G27: =IFERROR(AVERAGE(ReferrerEng_OT[Apr]),"") | H27: =IFERROR(AVERAGE(ReferrerEng_OT[May]),"") | I27: =IFERROR(AVERAGE(ReferrerEng_OT[June]),"") | J27: =IFERROR(AVERAGE(ReferrerEng_OT[July]),"") | K27: =IFERROR(AVERAGE(ReferrerEng_OT[Aug]),"") | L27: =IFERROR(AVERAGE(ReferrerEng_OT[Sept]),"") | M27: =IFERROR(AVERAGE(ReferrerEng_OT[Oct]),"") | N27: =IFERROR(AVERAGE(ReferrerEng_OT[Nov]),"") | O27: =IFERROR(AVERAGE(ReferrerEng_OT[Dec]),"") | P27: =IFERROR(AVERAGEIF(D27:O27, ">0"),"")
C28: Capacity Building & Use of NDIS Funding | D28: =IFERROR(AVERAGE(Capacity_OT[Jan]),"") | E28: =IFERROR(AVERAGE(Capacity_OT[Feb]),"") | F28: =IFERROR(AVERAGE(Capacity_OT[Mar]),"") | G28: =IFERROR(AVERAGE(Capacity_OT[Apr]),"") | H28: =IFERROR(AVERAGE(Capacity_OT[May]),"") | I28: =IFERROR(AVERAGE(Capacity_OT[June]),"") | J28: =IFERROR(AVERAGE(Capacity_OT[July]),"") | K28: =IFERROR(AVERAGE(Capacity_OT[Aug]),"") | L28: =IFERROR(AVERAGE(Capacity_OT[Sept]),"") | M28: =IFERROR(AVERAGE(Capacity_OT[Oct]),"") | N28: =IFERROR(AVERAGE(Capacity_OT[Nov]),"") | O28: =IFERROR(AVERAGE(Capacity_OT[Dec]),"") | P28: =IFERROR(AVERAGEIF(D28:O28, ">0"),"")
C29: Team Contribution, Attitude & Clinical Growth | D29: =IFERROR(AVERAGE(Attitude_OT[Jan]),"") | E29: =IFERROR(AVERAGE(Attitude_OT[Feb]),"") | F29: =IFERROR(AVERAGE(Attitude_OT[Mar]),"") | G29: =IFERROR(AVERAGE(Attitude_OT[Apr]),"") | H29: =IFERROR(AVERAGE(Attitude_OT[May]),"") | I29: =IFERROR(AVERAGE(Attitude_OT[June]),"") | J29: =IFERROR(AVERAGE(Attitude_OT[July]),"") | K29: =IFERROR(AVERAGE(Attitude_OT[Aug]),"") | L29: =IFERROR(AVERAGE(Attitude_OT[Sept]),"") | M29: =IFERROR(AVERAGE(Attitude_OT[Oct]),"") | N29: =IFERROR(AVERAGE(Attitude_OT[Nov]),"") | O29: =IFERROR(AVERAGE(Attitude_OT[Dec]),"") | P29: =IFERROR(AVERAGEIF(D29:O29, ">0"),"")
D31: TEAM KPI'S
C32: Role | D32: Below | E32: Good | F32: Excellent
C33: Physiotherapists | D33: <5 | E33: 5-5.4 | F33: >5.4
C34: Occupational Therapists | D34: <4.3 | E34: 4.3-4.9 | F34: >4.9
C35: Other KPI's | D35: Unsatisfactory | E35: Needs improvement | F35: In progress | G35: Very Good | H35: Excellent
D36: <1.5 | E36: 1.5-2.5 | F36: 2.5-3.5 | G36: 3.5-4.5 | H36: 4.5-5

Sheet KPI Dashboard South
B2: Team South | C2: Beth | Y2: 5
Y3: 4
Y4: 3
Y5: 2
B6: Team Average | C6: Jan | D6: Feb | E6: Mar | F6: Apr | G6: May | H6: June | I6: July | J6: Aug | K6: Sept | L6: Oct | M6: Nov | N6: Dec | O6: Average | Q6: TEAM KPI'S | Y6: 1
B7: Billings | C7: =IF(SUMIFS(FTETable[Jan], FTETable[Team], "Physio_South")=0, "", SUMIFS(FTETable[Jan], FTETable[Team], "Physio_South") / SUMIFS(FTETable[FTE], FTETable[Team], "Physio_South", FTETable[Jan], ">0")) | D7: =IF(SUMIFS(FTETable[Feb], FTETable[Team], "Physio_South")=0, "", SUMIFS(FTETable[Feb], FTETable[Team], "Physio_South") / SUMIFS(FTETable[FTE], FTETable[Team], "Physio_South", FTETable[Feb], ">0")) | E7: =IF(SUMIFS(FTETable[Mar], FTETable[Team], "Physio_South")=0, "", SUMIFS(FTETable[Mar], FTETable[Team], "Physio_South") / SUMIFS(FTETable[FTE], FTETable[Team], "Physio_South", FTETable[Mar], ">0")) | F7: =IF(SUMIFS(FTETable[Apr], FTETable[Team], "Physio_South")=0, "", SUMIFS(FTETable[Apr], FTETable[Team], "Physio_South") / SUMIFS(FTETable[FTE], FTETable[Team], "Physio_South", FTETable[Apr], ">0")) | G7: =IF(SUMIFS(FTETable[May], FTETable[Team], "Physio_South")=0, "", SUMIFS(FTETable[May], FTETable[Team], "Physio_South") / SUMIFS(FTETable[FTE], FTETable[Team], "Physio_South", FTETable[May], ">0")) | H7: =IF(SUMIFS(FTETable[June], FTETable[Team], "Physio_South")=0, "", SUMIFS(FTETable[June], FTETable[Team], "Physio_South") / SUMIFS(FTETable[FTE], FTETable[Team], "Physio_South", FTETable[June], ">0")) | I7: =IF(SUMIFS(FTETable[July], FTETable[Team], "Physio_South")=0, "", SUMIFS(FTETable[July], FTETable[Team], "Physio_South") / SUMIFS(FTETable[FTE], FTETable[Team], "Physio_South", FTETable[July], ">0")) | J7: =IF(SUMIFS(FTETable[Aug], FTETable[Team], "Physio_South")=0, "", SUMIFS(FTETable[Aug], FTETable[Team], "Physio_South") / SUMIFS(FTETable[FTE], FTETable[Team], "Physio_South", FTETable[Aug], ">0")) | K7: =IF(SUMIFS(FTETable[Sept], FTETable[Team], "Physio_South")=0, "", SUMIFS(FTETable[Sept], FTETable[Team], "Physio_South") / SUMIFS(FTETable[FTE], FTETable[Team], "Physio_South", FTETable[Sept], ">0")) | L7: =IF(SUMIFS(FTETable[Oct], FTETable[Team], "Physio_South")=0, "", SUMIFS(FTETable[Oct], FTETable[Team], "Physio_South") / SUMIFS(FTETable[FTE], FTETable[Team], "Physio_South", FTETable[Oct], ">0")) | M7: =IF(SUMIFS(FTETable[Nov], FTETable[Team], "Physio_South")=0, "", SUMIFS(FTETable[Nov], FTETable[Team], "Physio_South") / SUMIFS(FTETable[FTE], FTETable[Team], "Physio_South", FTETable[Nov], ">0")) | N7: =IF(SUMIFS(FTETable[Dec], FTETable[Team], "Physio_South")=0, "", SUMIFS(FTETable[Dec], FTETable[Team], "Physio_South") / SUMIFS(FTETable[FTE], FTETable[Team], "Physio_South", FTETable[Dec], ">0")) | O7: =IFERROR(AVERAGEIF(C7:N7, ">0"),"") | Q7: Team Billings | S7: Below | T7: Good | U7: Excellent
B8: Ceased Services | C8: =IFERROR(AVERAGE(Ceased_South[Jan]),"") | D8: =IFERROR(AVERAGE(Ceased_South[Feb]),"") | E8: =IFERROR(AVERAGE(Ceased_South[Mar]),"") | F8: =IFERROR(AVERAGE(Ceased_South[Apr]),"") | G8: =IFERROR(AVERAGE(Ceased_South[May]),"") | H8: =IFERROR(AVERAGE(Ceased_South[June]),"") | I8: =IFERROR(AVERAGE(Ceased_South[July]),"") | J8: =IFERROR(AVERAGE(Ceased_South[Aug]),"") | K8: =IFERROR(AVERAGE(Ceased_South[Sept]),"") | L8: =IFERROR(AVERAGE(Ceased_South[Oct]),"") | M8: =IFERROR(AVERAGE(Ceased_South[Nov]),"") | N8: =IFERROR(AVERAGE(Ceased_South[Dec]),"") | O8: =IFERROR(AVERAGEIF(C8:N8, ">0"),"") | S8: <5 | T8: 5-5.4 | U8: >5.4
B9: Documentation | C9: =IFERROR(AVERAGE(Documentation_South[Jan]),"") | D9: =IFERROR(AVERAGE(Documentation_South[Feb]),"") | E9: =IFERROR(AVERAGE(Documentation_South[Mar]),"") | F9: =IFERROR(AVERAGE(Documentation_South[Apr]),"") | G9: =IFERROR(AVERAGE(Documentation_South[May]),"") | H9: =IFERROR(AVERAGE(Documentation_South[June]),"") | I9: =IFERROR(AVERAGE(Documentation_South[July]),"") | J9: =IFERROR(AVERAGE(Documentation_South[Aug]),"") | K9: =IFERROR(AVERAGE(Documentation_South[Sept]),"") | L9: =IFERROR(AVERAGE(Documentation_South[Oct]),"") | M9: =IFERROR(AVERAGE(Documentation_South[Nov]),"") | N9: =IFERROR(AVERAGE(Documentation_South[Dec]),"") | O9: =IFERROR(AVERAGEIF(C9:N9, ">0"),"") | Q9: Other KPI's | S9: Unsatisfactory | T9: Needs improvement | U9: In progress | V9: Very Good | W9: Excellent
B10: Admin & Operational Efficiency | C10: =IFERROR(AVERAGE(Admin_South[Jan]),"") | D10: =IFERROR(AVERAGE(Admin_South[Feb]),"") | E10: =IFERROR(AVERAGE(Admin_South[Mar]),"") | F10: =IFERROR(AVERAGE(Admin_South[Apr]),"") | G10: =IFERROR(AVERAGE(Admin_South[May]),"") | H10: =IFERROR(AVERAGE(Admin_South[June]),"") | I10: =IFERROR(AVERAGE(Admin_South[July]),"") | J10: =IFERROR(AVERAGE(Admin_South[Aug]),"") | K10: =IFERROR(AVERAGE(Admin_South[Sept]),"") | L10: =IFERROR(AVERAGE(Admin_South[Oct]),"") | M10: =IFERROR(AVERAGE(Admin_South[Nov]),"") | N10: =IFERROR(AVERAGE(Admin_South[Dec]),"") | O10: =IFERROR(AVERAGEIF(C10:N10, ">0"),"") | S10: <1.5 | T10: 1.5-2.5 | U10: 2.5-3.5 | V10: 3.5-4.5 | W10: 4.5-5
B11: Attitude, Learning, Collaboration & Client Impact | C11: =IFERROR(AVERAGE(Attitude_South[Jan]),"") | D11: =IFERROR(AVERAGE(Attitude_South[Feb]),"") | E11: =IFERROR(AVERAGE(Attitude_South[Mar]),"") | F11: =IFERROR(AVERAGE(Attitude_South[Apr]),"") | G11: =IFERROR(AVERAGE(Attitude_South[May]),"") | H11: =IFERROR(AVERAGE(Attitude_South[June]),"") | I11: =IFERROR(AVERAGE(Attitude_South[July]),"") | J11: =IFERROR(AVERAGE(Attitude_South[Aug]),"") | K11: =IFERROR(AVERAGE(Attitude_South[Sept]),"") | L11: =IFERROR(AVERAGE(Attitude_South[Oct]),"") | M11: =IFERROR(AVERAGE(Attitude_South[Nov]),"") | N11: =IFERROR(AVERAGE(Attitude_South[Dec]),"") | O11: =IFERROR(AVERAGEIF(C11:N11, ">0"),"")
B13: Billings | C13: Jan | D13: Feb | E13: Mar | F13: Apr | G13: May | H13: June | I13: July | J13: Aug | K13: Sept | L13: Oct | M13: Nov | N13: Dec | O13: Average | Q13: Billings
B14: Tom | O14: =IFERROR(AVERAGE(Billings_South[[#This Row],[Jan]:[Dec]]),"")
B15: Maddie | O15: =IFERROR(AVERAGE(Billings_South[[#This Row],[Jan]:[Dec]]),"") | S15: Below | T15: Good | U15: Excellent
B16: Andy | O16: =IFERROR(AVERAGE(Billings_South[[#This Row],[Jan]:[Dec]]),"") | Q16: Grad | S16: <4.5 | T16: 4.5-5 | U16: >5
B17: Beth | O17: =IFERROR(AVERAGE(Billings_South[[#This Row],[Jan]:[Dec]]),"") | Q17: Clinical Associate | S17: <5 | T17: 5-5.4 | U17: >5.4
B18: Felina | O18: =IFERROR(AVERAGE(Billings_South[[#This Row],[Jan]:[Dec]]),"") | Q18: Senior | S18: <5.4 | T18: 5.4-5.7 | U18: >5.7
B19: Janice | O19: =IFERROR(AVERAGE(Billings_South[[#This Row],[Jan]:[Dec]]),"")
B20: Raj | O20: =IFERROR(AVERAGE(Billings_South[[#This Row],[Jan]:[Dec]]),"")
B21: Steph | O21: =IFERROR(AVERAGE(Billings_South[[#This Row],[Jan]:[Dec]]),"") | Q21: Ceased Services
B22: Vincent | O22: =IFERROR(AVERAGE(Billings_South[[#This Row],[Jan]:[Dec]]),"") | Q22: Ceased Clients ÷ Active Clients (excluding respite & deceased)
B23: Kate | O23: =IFERROR(AVERAGE(Billings_South[[#This Row],[Jan]:[Dec]]),"")
B24: Shirley | O24: =IFERROR(AVERAGE(Billings_South[[#This Row],[Jan]:[Dec]]),"") | Q24: <2.5 | S24: Excellent
Q25: 2.5-4 | S25: Good
B26: Ceased Services | C26: Jan | D26: Feb | E26: Mar | F26: Apr | G26: May | H26: June | I26: July | J26: Aug | K26: Sept | L26: Oct | M26: Nov | N26: Dec | O26: Average | Q26: >4 | S26: Below
B27: Tom | O27: =IFERROR(AVERAGE(Ceased_South[[#This Row],[Jan]:[Dec]]),"")
B28: Maddie | O28: =IFERROR(AVERAGE(Ceased_South[[#This Row],[Jan]:[Dec]]),"")
B29: Andy | O29: =IFERROR(AVERAGE(Ceased_South[[#This Row],[Jan]:[Dec]]),"") | Q29: Documentation
B30: Beth | O30: =IFERROR(AVERAGE(Ceased_South[[#This Row],[Jan]:[Dec]]),"") | Q30: Clinical notes, service agreements, and reports.
B31: Felina | O31: =IFERROR(AVERAGE(Ceased_South[[#This Row],[Jan]:[Dec]]),"") | Q31: 5 | S31: Excellent | V31: Notes/reports completed on time, accurate, clinically sound, and advocate for client. Service agreements up to date.
B32: Janice | O32: =IFERROR(AVERAGE(Ceased_South[[#This Row],[Jan]:[Dec]]),"") | Q32: 4 | S32: Very Good | V32: Notes/reports generally completed on time and of good quality. Service agreements mostly up to date.
B33: Raj | O33: =IFERROR(AVERAGE(Ceased_South[[#This Row],[Jan]:[Dec]]),"") | Q33: 3 | S33: In Progress | V33: Notes/reports mostly on time. Clinical quality is developing, occasional revisions. Some service agreements need follow-up.
B34: Steph | O34: =IFERROR(AVERAGE(Ceased_South[[#This Row],[Jan]:[Dec]]),"") | Q34: 2 | S34: Needs Improvement | V34: Frequent delays in documentation. Clinical quality inconsistent, most service agreements not up to date.
B35: Vincent | O35: =IFERROR(AVERAGE(Ceased_South[[#This Row],[Jan]:[Dec]]),"") | Q35: 1 | S35: Unsatisfactory | V35: Notes and reports regularly late or missing. Clinical quality below standard. Service agreements not maintained.
B36: Kate | O36: =IFERROR(AVERAGE(Ceased_South[[#This Row],[Jan]:[Dec]]),"")
B37: Shirley | O37: =IFERROR(AVERAGE(Ceased_South[[#This Row],[Jan]:[Dec]]),"")
Q38: Admin & Operational Efficiency
B39: Documentation | C39: Jan | D39: Feb | E39: Mar | F39: Apr | G39: May | H39: June | I39: July | J39: Aug | K39: Sept | L39: Oct | M39: Nov | N39: Dec | O39: Average | Q39: Admin responsiveness, scheduling and bookings, service in Zanda, travel efficiency.
B40: Tom | O40: =IFERROR(AVERAGE(Documentation_South[[#This Row],[Jan]:[Dec]]),"") | Q40: 5 | S40: Excellent | V40: Responsive to admin. Appointments scheduled, confirmed & services in Zanda accurate/timely. Efficient travel.
B41: Maddie | O41: =IFERROR(AVERAGE(Documentation_South[[#This Row],[Jan]:[Dec]]),"") | Q41: 4 | S41: Very Good | V41: Generally responsive to admin. Most appointments scheduled and confirmed in a timely manner. Services entered in Zanda with occasional delays/minor errors. Travel mostly efficient.
B42: Andy | O42: =IFERROR(AVERAGE(Documentation_South[[#This Row],[Jan]:[Dec]]),"") | Q42: 3 | S42: In Progress | V42: Moderately responsive to admin. Some delays/inconsistencies in appointment scheduling or confirmation. Zanda services entry late or incomplete. Travel planning can be improved.
...

Sheet KPI Dashboard North
B2: Team North | C2: Marco | Y2: 5
Y3: 4
Y4: 3
Y5: 2
B6: Team Average | C6: Jan | D6: Feb | E6: Mar | F6: Apr | G6: May | H6: June | I6: July | J6: Aug | K6: Sept | L6: Oct | M6: Nov | N6: Dec | O6: Average | Q6: TEAM KPI'S AND AVERAGES | Y6: 1 | AC6: 2 | AD6: 4
B7: Billings | C7: =IF(SUMIFS(FTETable[Jan], FTETable[Team], "Physio_North")=0, "", SUMIFS(FTETable[Jan], FTETable[Team], "Physio_North") / SUMIFS(FTETable[FTE], FTETable[Team], "Physio_North", FTETable[Jan], ">0")) | D7: =IF(SUMIFS(FTETable[Feb], FTETable[Team], "Physio_North")=0, "", SUMIFS(FTETable[Feb], FTETable[Team], "Physio_North") / SUMIFS(FTETable[FTE], FTETable[Team], "Physio_North", FTETable[Feb], ">0")) | E7: =IF(SUMIFS(FTETable[Mar], FTETable[Team], "Physio_North")=0, "", SUMIFS(FTETable[Mar], FTETable[Team], "Physio_North") / SUMIFS(FTETable[FTE], FTETable[Team], "Physio_North", FTETable[Mar], ">0")) | F7: =IF(SUMIFS(FTETable[Apr], FTETable[Team], "Physio_North")=0, "", SUMIFS(FTETable[Apr], FTETable[Team], "Physio_North") / SUMIFS(FTETable[FTE], FTETable[Team], "Physio_North", FTETable[Apr], ">0")) | G7: =IF(SUMIFS(FTETable[May], FTETable[Team], "Physio_North")=0, "", SUMIFS(FTETable[May], FTETable[Team], "Physio_North") / SUMIFS(FTETable[FTE], FTETable[Team], "Physio_North", FTETable[May], ">0")) | H7: =IF(SUMIFS(FTETable[June], FTETable[Team], "Physio_North")=0, "", SUMIFS(FTETable[June], FTETable[Team], "Physio_North") / SUMIFS(FTETable[FTE], FTETable[Team], "Physio_North", FTETable[June], ">0")) | I7: =IF(SUMIFS(FTETable[July], FTETable[Team], "Physio_North")=0, "", SUMIFS(FTETable[July], FTETable[Team], "Physio_North") / SUMIFS(FTETable[FTE], FTETable[Team], "Physio_North", FTETable[July], ">0")) | J7: =IF(SUMIFS(FTETable[Aug], FTETable[Team], "Physio_North")=0, "", SUMIFS(FTETable[Aug], FTETable[Team], "Physio_North") / SUMIFS(FTETable[FTE], FTETable[Team], "Physio_North", FTETable[Aug], ">0")) | K7: =IF(SUMIFS(FTETable[Sept], FTETable[Team], "Physio_North")=0, "", SUMIFS(FTETable[Sept], FTETable[Team], "Physio_North") / SUMIFS(FTETable[FTE], FTETable[Team], "Physio_North", FTETable[Sept], ">0")) | L7: =IF(SUMIFS(FTETable[Oct], FTETable[Team], "Physio_North")=0, "", SUMIFS(FTETable[Oct], FTETable[Team], "Physio_North") / SUMIFS(FTETable[FTE], FTETable[Team], "Physio_North", FTETable[Oct], ">0")) | M7: =IF(SUMIFS(FTETable[Nov], FTETable[Team], "Physio_North")=0, "", SUMIFS(FTETable[Nov], FTETable[Team], "Physio_North") / SUMIFS(FTETable[FTE], FTETable[Team], "Physio_North", FTETable[Nov], ">0")) | N7: =IF(SUMIFS(FTETable[Dec], FTETable[Team], "Physio_North")=0, "", SUMIFS(FTETable[Dec], FTETable[Team], "Physio_North") / SUMIFS(FTETable[FTE], FTETable[Team], "Physio_North", FTETable[Dec], ">0")) | O7: =IFERROR(AVERAGEIF(C7:N7, ">0"),"") | Q7: Team Billings Averages | S7: Below | T7: Good | U7: Excellent | V7: Month | AC7: 1 | AD7: 5
B8: Ceased Services | C8: =IFERROR(AVERAGE(Ceased_North[Jan]),"") | D8: =IFERROR(AVERAGE(Ceased_North[Feb]),"") | E8: =IFERROR(AVERAGE(Ceased_North[Mar]),"") | F8: =IFERROR(AVERAGE(Ceased_North[Apr]),"") | G8: =IFERROR(AVERAGE(Ceased_North[May]),"") | H8: =IFERROR(AVERAGE(Ceased_North[June]),"") | I8: =IFERROR(AVERAGE(Ceased_North[July]),"") | J8: =IFERROR(AVERAGE(Ceased_North[Aug]),"") | K8: =IFERROR(AVERAGE(Ceased_North[Sept]),"") | L8: =IFERROR(AVERAGE(Ceased_North[Oct]),"") | M8: =IFERROR(AVERAGE(Ceased_North[Nov]),"") | N8: =IFERROR(AVERAGE(Ceased_North[Dec]),"") | O8: =IFERROR(AVERAGEIF(C8:N8, ">0"),"") | S8: <5 | T8: 5-5.4 | U8: >5.4 | V8: 46023
B9: Documentation | C9: =IFERROR(AVERAGE(Documentation_North[Jan]),"") | D9: =IFERROR(AVERAGE(Documentation_North[Feb]),"") | E9: =IFERROR(AVERAGE(Documentation_North[Mar]),"") | F9: =IFERROR(AVERAGE(Documentation_North[Apr]),"") | G9: =IFERROR(AVERAGE(Documentation_North[May]),"") | H9: =IFERROR(AVERAGE(Documentation_North[June]),"") | I9: =IFERROR(AVERAGE(Documentation_North[July]),"") | J9: =IFERROR(AVERAGE(Documentation_North[Aug]),"") | K9: =IFERROR(AVERAGE(Documentation_North[Sept]),"") | L9: =IFERROR(AVERAGE(Documentation_North[Oct]),"") | M9: =IFERROR(AVERAGE(Documentation_North[Nov]),"") | N9: =IFERROR(AVERAGE(Documentation_North[Dec]),"") | O9: =IFERROR(AVERAGEIF(C9:N9, ">0"),"") | S9: <4.99 | T9: 4.99-5.39 | U9: >5.39 | V9: 46054
B10: Admin & Operational Efficiency | C10: =IFERROR(AVERAGE(Admin_North[Jan]),"") | D10: =IFERROR(AVERAGE(Admin_North[Feb]),"") | E10: =IFERROR(AVERAGE(Admin_North[Mar]),"") | F10: =IFERROR(AVERAGE(Admin_North[Apr]),"") | G10: =IFERROR(AVERAGE(Admin_North[May]),"") | H10: =IFERROR(AVERAGE(Admin_North[June]),"") | I10: =IFERROR(AVERAGE(Admin_North[July]),"") | J10: =IFERROR(AVERAGE(Admin_North[Aug]),"") | K10: =IFERROR(AVERAGE(Admin_North[Sept]),"") | L10: =IFERROR(AVERAGE(Admin_North[Oct]),"") | M10: =IFERROR(AVERAGE(Admin_North[Nov]),"") | N10: =IFERROR(AVERAGE(Admin_North[Dec]),"") | O10: =IFERROR(AVERAGEIF(C10:N10, ">0"),"")
B11: Attitude, Learning, Collaboration & Client Impact | C11: =IFERROR(AVERAGE(Attitude_North[Jan]),"") | D11: =IFERROR(AVERAGE(Attitude_North[Feb]),"") | E11: =IFERROR(AVERAGE(Attitude_North[Mar]),"") | F11: =IFERROR(AVERAGE(Attitude_North[Apr]),"") | G11: =IFERROR(AVERAGE(Attitude_North[May]),"") | H11: =IFERROR(AVERAGE(Attitude_North[June]),"") | I11: =IFERROR(AVERAGE(Attitude_North[July]),"") | J11: =IFERROR(AVERAGE(Attitude_North[Aug]),"") | K11: =IFERROR(AVERAGE(Attitude_North[Sept]),"") | L11: =IFERROR(AVERAGE(Attitude_North[Oct]),"") | M11: =IFERROR(AVERAGE(Attitude_North[Nov]),"") | N11: =IFERROR(AVERAGE(Attitude_North[Dec]),"") | O11: =IFERROR(AVERAGEIF(C11:N11, ">0"),"") | Q11: Other KPI Averages | S11: Unsatisfactory | T11: Needs improvement | U11: In progress | V11: Very Good | W11: Excellent
S12: <1.5 | T12: 1.5-2.5 | U12: 2.5-3.5 | V12: 3.5-4.5 | W12: 4.5-5
B13: Billings | C13: Jan | D13: Feb | E13: Mar | F13: Apr | G13: May | H13: June | I13: July | J13: Aug | K13: Sept | L13: Oct | M13: Nov | N13: Dec | O13: Average
B14: Marco | O14: =IFERROR(AVERAGE(Billings_North[[#This Row],[Jan]:[Dec]]),"")
B15: Danny | O15: =IFERROR(AVERAGE(Billings_North[[#This Row],[Jan]:[Dec]]),"") | Q15: Billings
B16: Alice | O16: =IFERROR(AVERAGE(Billings_North[[#This Row],[Jan]:[Dec]]),"")
B17: April | O17: =IFERROR(AVERAGE(Billings_North[[#This Row],[Jan]:[Dec]]),"") | S17: Below | T17: Good | U17: Excellent
B18: Chris | O18: =IFERROR(AVERAGE(Billings_North[[#This Row],[Jan]:[Dec]]),"") | Q18: Grad | S18: <4.5 | T18: 4.5-5 | U18: >5
B19: Emilie | O19: =IFERROR(AVERAGE(Billings_North[[#This Row],[May]:[Dec]]),"") | Q19: Clinical Associate | S19: <5 | T19: 5-5.4 | U19: >5.4
B20: Eva | O20: =IFERROR(AVERAGE(Billings_North[[#This Row],[May]:[Dec]]),"") | Q20: Senior | S20: <5.4 | T20: 5.4-5.7 | U20: >5.7
B21: Jackson | O21: =IFERROR(AVERAGE(Billings_North[[#This Row],[Jan]:[Dec]]),"")
B22: Jay | O22: =IFERROR(AVERAGE(Billings_North[[#This Row],[Jan]:[Dec]]),"")
B23: Jaymee | O23: =IFERROR(AVERAGE(Billings_North[[#This Row],[May]:[Dec]]),"") | Q23: Ceased Services
Q24: Ceased Clients ÷ Active Clients (excluding respite & deceased)
B25: Ceased Services | C25: Jan | D25: Feb | E25: Mar | F25: Apr | G25: May | H25: June | I25: July | J25: Aug | K25: Sept | L25: Oct | M25: Nov | N25: Dec | O25: Average
B26: Marco | O26: =IFERROR(AVERAGE(Ceased_North[[#This Row],[Jan]:[Dec]]),"") | Q26: <2.5 | S26: Excellent
B27: Danny | O27: =IFERROR(AVERAGE(Ceased_North[[#This Row],[Jan]:[Dec]]),"") | Q27: 2.5-4 | S27: Good
B28: Alice | O28: =IFERROR(AVERAGE(Ceased_North[[#This Row],[Jan]:[Dec]]),"") | Q28: >4 | S28: Below
B29: April | O29: =IFERROR(AVERAGE(Ceased_North[[#This Row],[Jan]:[Dec]]),"")
B30: Chris | O30: =IFERROR(AVERAGE(Ceased_North[[#This Row],[Jan]:[Dec]]),"")
B31: Emilie | O31: =IFERROR(AVERAGE(Ceased_North[[#This Row],[Jan]:[Dec]]),"") | Q31: Documentation
B32: Eva | O32: =IFERROR(AVERAGE(Ceased_North[[#This Row],[Jan]:[Dec]]),"") | Q32: Clinical notes, service agreements, and reports.
B33: Jackson | O33: =IFERROR(AVERAGE(Ceased_North[[#This Row],[Jan]:[Dec]]),"") | Q33: 5 | S33: Excellent | V33: Notes/reports completed on time, accurate, clinically sound, and advocate for client. Service agreements up to date.
B34: Jay | O34: =IFERROR(AVERAGE(Ceased_North[[#This Row],[Jan]:[Dec]]),"") | Q34: 4 | S34: Very Good | V34: Notes/reports generally completed on time and of good quality. Service agreements mostly up to date.
B35: Jaymee | O35: =IFERROR(AVERAGE(Ceased_North[[#This Row],[Jan]:[Dec]]),"") | Q35: 3 | S35: In Progress | V35: Notes/reports mostly on time. Clinical quality is developing, occasional revisions. Some service agreements need follow-up.
Q36: 2 | S36: Needs Improvement | V36: Frequent delays in documentation. Clinical quality inconsistent, most service agreements not up to date.
B37: Documentation | C37: Jan | D37: Feb | E37: Mar | F37: Apr | G37: May | H37: June | I37: July | J37: Aug | K37: Sept | L37: Oct | M37: Nov | N37: Dec | O37: Average | Q37: 1 | S37: Unsatisfactory | V37: Notes and reports regularly late or missing. Clinical quality below standard. Service agreements not maintained.
B38: Marco | O38: =IFERROR(AVERAGE(Documentation_North[[#This Row],[Jan]:[Dec]]),"")
B39: Danny | O39: =IFERROR(AVERAGE(Documentation_North[[#This Row],[Jan]:[Dec]]),"")
B40: Alice | O40: =IFERROR(AVERAGE(Documentation_North[[#This Row],[Jan]:[Dec]]),"") | Q40: Admin & Operational Efficiency
B41: April | O41: =IFERROR(AVERAGE(Documentation_North[[#This Row],[Jan]:[Dec]]),"") | Q41: Admin responsiveness, scheduling and bookings, service in Zanda, travel efficiency.
...

Sheet KPI Dashboard OT
B2: Team Leader | C2: Josephine Lee | Y2: 5
Y3: 4
Y4: 3
Y5: 2
B6: Team Average | C6: Jan | D6: Feb | E6: Mar | F6: Apr | G6: May | H6: June | I6: July | J6: Aug | K6: Sept | L6: Oct | M6: Nov | N6: Dec | O6: Average | Q6: TEAM KPI'S | Y6: 1
B7: Billings | C7: =IF(SUMIFS(FTETable[Jan], FTETable[Team], "OT")=0, "", SUMIFS(FTETable[Jan], FTETable[Team], "OT") / SUMIFS(FTETable[FTE], FTETable[Team], "OT", FTETable[Jan], ">0")) | D7: =IF(SUMIFS(FTETable[Feb], FTETable[Team], "OT")=0, "", SUMIFS(FTETable[Feb], FTETable[Team], "OT") / SUMIFS(FTETable[FTE], FTETable[Team], "OT", FTETable[Feb], ">0")) | E7: =IF(SUMIFS(FTETable[Mar], FTETable[Team], "OT")=0, "", SUMIFS(FTETable[Mar], FTETable[Team], "OT") / SUMIFS(FTETable[FTE], FTETable[Team], "OT", FTETable[Mar], ">0")) | F7: =IF(SUMIFS(FTETable[Apr], FTETable[Team], "OT")=0, "", SUMIFS(FTETable[Apr], FTETable[Team], "OT") / SUMIFS(FTETable[FTE], FTETable[Team], "OT", FTETable[Apr], ">0")) | G7: =IF(SUMIFS(FTETable[May], FTETable[Team], "OT")=0, "", SUMIFS(FTETable[May], FTETable[Team], "OT") / SUMIFS(FTETable[FTE], FTETable[Team], "OT", FTETable[May], ">0")) | H7: =IF(SUMIFS(FTETable[June], FTETable[Team], "OT")=0, "", SUMIFS(FTETable[June], FTETable[Team], "OT") / SUMIFS(FTETable[FTE], FTETable[Team], "OT", FTETable[June], ">0")) | I7: =IF(SUMIFS(FTETable[July], FTETable[Team], "OT")=0, "", SUMIFS(FTETable[July], FTETable[Team], "OT") / SUMIFS(FTETable[FTE], FTETable[Team], "OT", FTETable[July], ">0")) | J7: =IF(SUMIFS(FTETable[Aug], FTETable[Team], "OT")=0, "", SUMIFS(FTETable[Aug], FTETable[Team], "OT") / SUMIFS(FTETable[FTE], FTETable[Team], "OT", FTETable[Aug], ">0")) | K7: =IF(SUMIFS(FTETable[Sept], FTETable[Team], "OT")=0, "", SUMIFS(FTETable[Sept], FTETable[Team], "OT") / SUMIFS(FTETable[FTE], FTETable[Team], "OT", FTETable[Sept], ">0")) | L7: =IF(SUMIFS(FTETable[Oct], FTETable[Team], "OT")=0, "", SUMIFS(FTETable[Oct], FTETable[Team], "OT") / SUMIFS(FTETable[FTE], FTETable[Team], "OT", FTETable[Oct], ">0")) | M7: =IF(SUMIFS(FTETable[Nov], FTETable[Team], "OT")=0, "", SUMIFS(FTETable[Nov], FTETable[Team], "OT") / SUMIFS(FTETable[FTE], FTETable[Team], "OT", FTETable[Nov], ">0")) | N7: =IF(SUMIFS(FTETable[Dec], FTETable[Team], "OT")=0, "", SUMIFS(FTETable[Dec], FTETable[Team], "OT") / SUMIFS(FTETable[FTE], FTETable[Team], "OT", FTETable[Dec], ">0")) | O7: =IFERROR(AVERAGEIF(C7:N7, ">0"),"") | Q7: Team Billings | S7: Below | T7: Good | U7: Excellent
B8: Operational Efficiency, Compliance & Admin Responsiveness | C8: =IFERROR(AVERAGE(Compliance_OT[Jan]),"") | D8: =IFERROR(AVERAGE(Compliance_OT[Feb]),"") | E8: =IFERROR(AVERAGE(Compliance_OT[Mar]),"") | F8: =IFERROR(AVERAGE(Compliance_OT[Apr]),"") | G8: =IFERROR(AVERAGE(Compliance_OT[May]),"") | H8: =IFERROR(AVERAGE(Compliance_OT[June]),"") | I8: =IFERROR(AVERAGE(Compliance_OT[July]),"") | J8: =IFERROR(AVERAGE(Compliance_OT[Aug]),"") | K8: =IFERROR(AVERAGE(Compliance_OT[Sept]),"") | L8: =IFERROR(AVERAGE(Compliance_OT[Oct]),"") | M8: =IFERROR(AVERAGE(Compliance_OT[Nov]),"") | N8: =IFERROR(AVERAGE(Compliance_OT[Dec]),"") | O8: =IFERROR(AVERAGEIF(C8:N8, ">0"),"") | S8: <4.3 | T8: 4.3-4.9 | U8: >4.9
B9: Client & Referrer Satisfaction | C9: =IFERROR(AVERAGE(ReferrerEng_OT[Jan]),"") | D9: =IFERROR(AVERAGE(ReferrerEng_OT[Feb]),"") | E9: =IFERROR(AVERAGE(ReferrerEng_OT[Mar]),"") | F9: =IFERROR(AVERAGE(ReferrerEng_OT[Apr]),"") | G9: =IFERROR(AVERAGE(ReferrerEng_OT[May]),"") | H9: =IFERROR(AVERAGE(ReferrerEng_OT[June]),"") | I9: =IFERROR(AVERAGE(ReferrerEng_OT[July]),"") | J9: =IFERROR(AVERAGE(ReferrerEng_OT[Aug]),"") | K9: =IFERROR(AVERAGE(ReferrerEng_OT[Sept]),"") | L9: =IFERROR(AVERAGE(ReferrerEng_OT[Oct]),"") | M9: =IFERROR(AVERAGE(ReferrerEng_OT[Nov]),"") | N9: =IFERROR(AVERAGE(ReferrerEng_OT[Dec]),"") | O9: =IFERROR(AVERAGEIF(C9:N9, ">0"),"") | Q9: Other KPI's | S9: Unsatisfactory | T9: Needs improvement | U9: In progress | V9: Very Good | W9: Excellent
B10: Capacity Building & Use of NDIS Funding | C10: =IFERROR(AVERAGE(Capacity_OT[Jan]),"") | D10: =IFERROR(AVERAGE(Capacity_OT[Feb]),"") | E10: =IFERROR(AVERAGE(Capacity_OT[Mar]),"") | F10: =IFERROR(AVERAGE(Capacity_OT[Apr]),"") | G10: =IFERROR(AVERAGE(Capacity_OT[May]),"") | H10: =IFERROR(AVERAGE(Capacity_OT[June]),"") | I10: =IFERROR(AVERAGE(Capacity_OT[July]),"") | J10: =IFERROR(AVERAGE(Capacity_OT[Aug]),"") | K10: =IFERROR(AVERAGE(Capacity_OT[Sept]),"") | L10: =IFERROR(AVERAGE(Capacity_OT[Oct]),"") | M10: =IFERROR(AVERAGE(Capacity_OT[Nov]),"") | N10: =IFERROR(AVERAGE(Capacity_OT[Dec]),"") | O10: =IFERROR(AVERAGEIF(C10:N10, ">0"),"") | S10: <1.5 | T10: 1.5-2.5 | U10: 2.5-3.5 | V10: 3.5-4.5 | W10: 4.5-5
B11: Team Contribution, Attitude & Clinical Growth | C11: =IFERROR(AVERAGE(Attitude_OT[Jan]),"") | D11: =IFERROR(AVERAGE(Attitude_OT[Feb]),"") | E11: =IFERROR(AVERAGE(Attitude_OT[Mar]),"") | F11: =IFERROR(AVERAGE(Attitude_OT[Apr]),"") | G11: =IFERROR(AVERAGE(Attitude_OT[May]),"") | H11: =IFERROR(AVERAGE(Attitude_OT[June]),"") | I11: =IFERROR(AVERAGE(Attitude_OT[July]),"") | J11: =IFERROR(AVERAGE(Attitude_OT[Aug]),"") | K11: =IFERROR(AVERAGE(Attitude_OT[Sept]),"") | L11: =IFERROR(AVERAGE(Attitude_OT[Oct]),"") | M11: =IFERROR(AVERAGE(Attitude_OT[Nov]),"") | N11: =IFERROR(AVERAGE(Attitude_OT[Dec]),"") | O11: =IFERROR(AVERAGEIF(C11:N11, ">0"),"")
B13: Billings | C13: Jan | D13: Feb | E13: Mar | F13: Apr | G13: May | H13: June | I13: July | J13: Aug | K13: Sept | L13: Oct | M13: Nov | N13: Dec | O13: Average | Q13: Billings
B14: Josephine | O14: =IFERROR(AVERAGE(Billings_OT[[#This Row],[Jan]:[Dec]]),"")
B15: Caitlin | O15: =IFERROR(AVERAGE(Billings_OT[[#This Row],[Jan]:[Dec]]),"") | S15: Below | T15: Good | U15: Excellent
B16: Charlotte | O16: =IFERROR(AVERAGE(Billings_OT[[#This Row],[Jan]:[Dec]]),"") | Q16: Grad | S16: <4 | T16: 4-4.8 | U16: >4.8
B17: Isabella | O17: =IFERROR(AVERAGE(Billings_OT[[#This Row],[Jan]:[Dec]]),"") | Q17: CA | S17: <4.5 | T17: 4.5-5 | U17: >5
B18: Lynn | O18: =IFERROR(AVERAGE(Billings_OT[[#This Row],[Jan]:[Dec]]),"") | Q18: Senior | S18: <4.8 | T18: 4.8-5.2 | U18: >5.2
B19: Portia | O19: =IFERROR(AVERAGE(Billings_OT[[#This Row],[Jan]:[Dec]]),"")
B20: Bao | O20: =IFERROR(AVERAGE(Billings_OT[[#This Row],[Jan]:[Dec]]),"")
B21: Jiayee | O21: =IFERROR(AVERAGE(Billings_OT[[#This Row],[Jan]:[Dec]]),"") | Q21: Operational Efficiency, Compliance & Admin Responsiveness
B22: Rainie | O22: =IFERROR(AVERAGE(Billings_OT[[#This Row],[Jan]:[Dec]]),"") | Q22: Clinical notes, service agreements, invoicing, travel efficiency, & admin communication.
B23: Sabrina | O23: =IFERROR(AVERAGE(Billings_OT[[#This Row],[Jan]:[Dec]]),"") | Q23: 5 | S23: Excellent | V23: Always submits accurate documentation on time, responds promptly to admin, and plans travel efficiently. Follows processes consistently.
Q24: 4 | S24: Very Good | V24: Mostly accurate and timely with documentation and admin replies. Travel is generally efficient.
B25: Operational Efficiency, Compliance & Admin Responsiveness | C25: Jan | D25: Feb | E25: Mar | F25: Apr | G25: May | H25: June | I25: July | J25: Aug | K25: Sept | L25: Oct | M25: Nov | N25: Dec | O25: Average | Q25: 3 | S25: In Progress | V25: Some delays or inconsistencies in documentation or admin responsiveness. Travel planning could improve.
B26: Josephine | O26: =IFERROR(AVERAGE(Compliance_OT[[#This Row],[Jan]:[Dec]]),"") | Q26: 2 | S26: Needs Improvement | V26: Frequent delays or inefficiencies. Often slow to respond to admin. Needs reminders.
B27: Caitlin | O27: =IFERROR(AVERAGE(Compliance_OT[[#This Row],[Jan]:[Dec]]),"") | Q27: 1 | S27: Unsatisfactory | V27: Often late or inaccurate. Poor planning, poor admin responsiveness, and non-compliance with systems.
B28: Charlotte | O28: =IFERROR(AVERAGE(Compliance_OT[[#This Row],[Jan]:[Dec]]),"")
B29: Isabella | O29: =IFERROR(AVERAGE(Compliance_OT[[#This Row],[Jan]:[Dec]]),"") | Q29: Client & Referrer Satisfaction
B30: Lynn | O30: =IFERROR(AVERAGE(Compliance_OT[[#This Row],[Jan]:[Dec]]),"") | Q30: Looks at how well we keep both clients and referrers in the loop and build rapport.
B31: Portia | O31: =IFERROR(AVERAGE(Compliance_OT[[#This Row],[Jan]:[Dec]]),"") | Q31: 5 | S31: Excellent | V31: Proactive and clear communication. Strong relationships. Regular positive feedback, great client results.
B32: Bao | O32: =IFERROR(AVERAGE(Compliance_OT[[#This Row],[Jan]:[Dec]]),"") | Q32: 4 | S32: Very Good | V32: Communicates well most of the time. Positive rapport.
B33: Jiayee | O33: =IFERROR(AVERAGE(Compliance_OT[[#This Row],[Jan]:[Dec]]),"") | Q33: 3 | S33: In Progress | V33: Generally responsive but a bit inconsistent.
B34: Rainie | O34: =IFERROR(AVERAGE(Compliance_OT[[#This Row],[Jan]:[Dec]]),"") | Q34: 2 | S34: Needs Improvement | V34: Delays or lack of clarity. Occasional negative feedback.
B35: Sabrina | O35: =IFERROR(AVERAGE(Compliance_OT[[#This Row],[Jan]:[Dec]]),"") | Q35: 1 | S35: Unsatisfactory | V35: Rarely communicates effectively. Ongoing issues.
B37: Client & Referrer Satisfaction | C37: Jan | D37: Feb | E37: Mar | F37: Apr | G37: May | H37: June | I37: July | J37: Aug | K37: Sept | L37: Oct | M37: Nov | N37: Dec | O37: Average | Q37: Capacity Building & Use of NDIS Funding
B38: Josephine | O38: =IFERROR(AVERAGE(ReferrerEng_OT[[#This Row],[Jan]:[Dec]]),"") | Q38: Focus on follow-through and using funding in a way that supports outcomes.
B39: Caitlin | O39: =IFERROR(AVERAGE(ReferrerEng_OT[[#This Row],[Jan]:[Dec]]),"") | Q39: 5 | S39: Excellent | V39: Delivers meaningful follow-up aligned with recommendations. NDIS funding well utilised.
B40: Charlotte | O40: =IFERROR(AVERAGE(ReferrerEng_OT[[#This Row],[Jan]:[Dec]]),"") | Q40: 4 | S40: Very Good | V40: Follows through on most recommendations. Good use of funds.
B41: Isabella | O41: =IFERROR(AVERAGE(ReferrerEng_OT[[#This Row],[Jan]:[Dec]]),"") | Q41: 3 | S41: In Progress | V41: Some follow-up, but some opportunities missed.
B42: Lynn | O42: =IFERROR(AVERAGE(ReferrerEng_OT[[#This Row],[Jan]:[Dec]]),"") | Q42: 2 | S42: Needs Improvement | V42: Often doesn’t complete follow-up. Funding underused.
B43: Portia | O43: =IFERROR(AVERAGE(ReferrerEng_OT[[#This Row],[Jan]:[Dec]]),"") | Q43: 1 | S43: Unsatisfactory | V43: Rarely follows through. Consistently underutilised funding.
...

Sheet Ceased services
C2: CEASED SERVICES LOG
E5: January 2026 | H5: February 2026 | K5: March 2026 | N5: April 2026 | Q5: May 2026 | T5: June 2026 | W5: July 2026 | Z5: August 2026 | AC5: September 2026 | AF5: October 2026 | AI5: November 2026 | AL5: December 2026
C6: Team | D6: Therapist | E6: Active | F6: Ceased | G6: % | H6: Active | I6: Ceased | J6: % | K6: Active | L6: Ceased | M6: % | N6: Active | O6: Ceased | P6: % | Q6: Active | R6: Ceased | S6: % | T6: Active | U6: Ceased | V6: % | W6: Active | X6: Ceased | Y6: % | Z6: Active | AA6: Ceased | AB6: % | AC6: Active | AD6: Ceased | AE6: % | AF6: Active | AG6: Ceased | AH6: % | AI6: Active | AJ6: Ceased | AK6: % | AL6: Active | AM6: Ceased | AN6: %
C7: North | D7: Marco | E7: 42 | F7: 0 | G7: =IF(OR(E7="", F7=""), "", F7/E7) | H7: 44 | I7: 0 | J7: =IF(OR(H7="", I7=""), "", I7/H7) | K7: 47 | L7: 1 | M7: =IF(OR(K7="", L7=""), "", L7/K7) | N7: 46 | O7: 3 | P7: =IF(OR(N7="", O7=""), "", O7/N7) | W7: 42 | X7: 0 | Y7: =IF(OR(W7="", X7=""), "", X7/W7) | Z7: 44 | AA7: 0 | AB7: =IF(OR(Z7="", AA7=""), "", AA7/Z7) | AC7: 47 | AD7: 1 | AE7: =IF(OR(AC7="", AD7=""), "", AD7/AC7) | AF7: 46 | AG7: 3 | AH7: =IF(OR(AF7="", AG7=""), "", AG7/AF7)
C8: North | D8: Simran | E8: 47 | F8: 2 | G8: =IF(OR(E8="", F8=""), "", F8/E8) | H8: 48 | I8: 1 | J8: =IF(OR(H8="", I8=""), "", I8/H8) | K8: 51 | L8: 3 | M8: =IF(OR(K8="", L8=""), "", L8/K8) | N8: 53 | O8: 0 | P8: =IF(OR(N8="", O8=""), "", O8/N8) | W8: 47 | X8: 2 | Y8: =IF(OR(W8="", X8=""), "", X8/W8) | Z8: 48 | AA8: 1 | AB8: =IF(OR(Z8="", AA8=""), "", AA8/Z8) | AC8: 51 | AD8: 3 | AE8: =IF(OR(AC8="", AD8=""), "", AD8/AC8) | AF8: 53 | AG8: 0 | AH8: =IF(OR(AF8="", AG8=""), "", AG8/AF8)
C9: North | D9: Jay | E9: 61 | F9: 5 | G9: =IF(OR(E9="", F9=""), "", F9/E9) | H9: 57 | I9: 6 | J9: =IF(OR(H9="", I9=""), "", I9/H9) | K9: 58 | L9: 2 | M9: =IF(OR(K9="", L9=""), "", L9/K9) | N9: 58 | O9: 4 | P9: =IF(OR(N9="", O9=""), "", O9/N9) | W9: 61 | X9: 5 | Y9: =IF(OR(W9="", X9=""), "", X9/W9) | Z9: 57 | AA9: 6 | AB9: =IF(OR(Z9="", AA9=""), "", AA9/Z9) | AC9: 58 | AD9: 2 | AE9: =IF(OR(AC9="", AD9=""), "", AD9/AC9) | AF9: 58 | AG9: 4 | AH9: =IF(OR(AF9="", AG9=""), "", AG9/AF9)
C10: North | D10: Danny | E10: 23 | F10: 0 | G10: =IF(OR(E10="", F10=""), "", F10/E10) | H10: 25 | I10: 1 | J10: =IF(OR(H10="", I10=""), "", I10/H10) | K10: 20 | L10: 0 | M10: =IF(OR(K10="", L10=""), "", L10/K10) | N10: 20 | O10: 0 | P10: =IF(OR(N10="", O10=""), "", O10/N10) | W10: 23 | X10: 0 | Y10: =IF(OR(W10="", X10=""), "", X10/W10) | Z10: 25 | AA10: 1 | AB10: =IF(OR(Z10="", AA10=""), "", AA10/Z10) | AC10: 20 | AD10: 0 | AE10: =IF(OR(AC10="", AD10=""), "", AD10/AC10) | AF10: 20 | AG10: 0 | AH10: =IF(OR(AF10="", AG10=""), "", AG10/AF10)
C11: North | D11: Chris | E11: 39 | F11: 0 | G11: =IF(OR(E11="", F11=""), "", F11/E11) | H11: 43 | I11: 2 | J11: =IF(OR(H11="", I11=""), "", I11/H11) | K11: 42 | L11: 1 | M11: =IF(OR(K11="", L11=""), "", L11/K11) | N11: 49 | O11: 3 | P11: =IF(OR(N11="", O11=""), "", O11/N11) | W11: 39 | X11: 0 | Y11: =IF(OR(W11="", X11=""), "", X11/W11) | Z11: 43 | AA11: 2 | AB11: =IF(OR(Z11="", AA11=""), "", AA11/Z11) | AC11: 42 | AD11: 1 | AE11: =IF(OR(AC11="", AD11=""), "", AD11/AC11) | AF11: 49 | AG11: 3 | AH11: =IF(OR(AF11="", AG11=""), "", AG11/AF11)
C12: North | D12: Alice | E12: 54 | F12: 4 | G12: =IF(OR(E12="", F12=""), "", F12/E12) | H12: 55 | I12: 6 | J12: =IF(OR(H12="", I12=""), "", I12/H12) | K12: 57 | L12: 1 | M12: =IF(OR(K12="", L12=""), "", L12/K12) | N12: 54 | O12: 4 | P12: =IF(OR(N12="", O12=""), "", O12/N12) | W12: 54 | X12: 4 | Y12: =IF(OR(W12="", X12=""), "", X12/W12) | Z12: 55 | AA12: 6 | AB12: =IF(OR(Z12="", AA12=""), "", AA12/Z12) | AC12: 57 | AD12: 1 | AE12: =IF(OR(AC12="", AD12=""), "", AD12/AC12) | AF12: 54 | AG12: 4 | AH12: =IF(OR(AF12="", AG12=""), "", AG12/AF12)
C13: North | D13: Elizabeth | G13: =IF(OR(E13="", F13=""), "", F13/E13) | H13: 11 | I13: 1 | J13: =IF(OR(H13="", I13=""), "", I13/H13) | K13: 14 | L13: 0 | M13: =IF(OR(K13="", L13=""), "", L13/K13) | N13: 15 | O13: 0 | P13: =IF(OR(N13="", O13=""), "", O13/N13) | Y13: =IF(OR(W13="", X13=""), "", X13/W13) | Z13: 11 | AA13: 1 | AB13: =IF(OR(Z13="", AA13=""), "", AA13/Z13) | AC13: 14 | AD13: 0 | AE13: =IF(OR(AC13="", AD13=""), "", AD13/AC13) | AF13: 15 | AG13: 0 | AH13: =IF(OR(AF13="", AG13=""), "", AG13/AF13)
C14: North | D14: Eva | E14: 41 | F14: 3 | G14: =IF(OR(E14="", F14=""), "", F14/E14) | H14: 43 | I14: 2 | J14: =IF(OR(H14="", I14=""), "", I14/H14) | K14: 40 | L14: 2 | M14: =IF(OR(K14="", L14=""), "", L14/K14) | N14: 49 | O14: 1 | P14: =IF(OR(N14="", O14=""), "", O14/N14) | W14: 41 | X14: 3 | Y14: =IF(OR(W14="", X14=""), "", X14/W14) | Z14: 43 | AA14: 2 | AB14: =IF(OR(Z14="", AA14=""), "", AA14/Z14) | AC14: 40 | AD14: 2 | AE14: =IF(OR(AC14="", AD14=""), "", AD14/AC14) | AF14: 49 | AG14: 1 | AH14: =IF(OR(AF14="", AG14=""), "", AG14/AF14)
C15: South | D15: Maddie | E15: 21 | F15: 2 | G15: =IF(OR(E15="", F15=""), "", F15/E15) | H15: 17 | I15: 0 | J15: =IF(OR(H15="", I15=""), "", I15/H15) | K15: 17 | L15: 0 | M15: =IF(OR(K15="", L15=""), "", L15/K15) | N15: 20 | O15: 0 | P15: =IF(OR(N15="", O15=""), "", O15/N15) | W15: 21 | X15: 2 | Y15: =IF(OR(W15="", X15=""), "", X15/W15) | Z15: 17 | AA15: 0 | AB15: =IF(OR(Z15="", AA15=""), "", AA15/Z15) | AC15: 17 | AD15: 0 | AE15: =IF(OR(AC15="", AD15=""), "", AD15/AC15) | AF15: 20 | AG15: 0 | AH15: =IF(OR(AF15="", AG15=""), "", AG15/AF15)
C16: South | D16: Stephen | E16: 25 | F16: 3 | G16: =IF(OR(E16="", F16=""), "", F16/E16) | H16: 20 | I16: 1 | J16: =IF(OR(H16="", I16=""), "", I16/H16) | K16: 20 | L16: 0 | M16: =IF(OR(K16="", L16=""), "", L16/K16) | N16: 20 | O16: 0 | P16: =IF(OR(N16="", O16=""), "", O16/N16) | W16: 25 | X16: 3 | Y16: =IF(OR(W16="", X16=""), "", X16/W16) | Z16: 20 | AA16: 1 | AB16: =IF(OR(Z16="", AA16=""), "", AA16/Z16) | AC16: 20 | AD16: 0 | AE16: =IF(OR(AC16="", AD16=""), "", AD16/AC16) | AF16: 20 | AG16: 0 | AH16: =IF(OR(AF16="", AG16=""), "", AG16/AF16)
C17: South | D17: Beth | E17: 45 | F17: 1 | G17: =IF(OR(E17="", F17=""), "", F17/E17) | H17: 35 | I17: 2 | J17: =IF(OR(H17="", I17=""), "", I17/H17) | K17: 32 | L17: 1 | M17: =IF(OR(K17="", L17=""), "", L17/K17) | N17: 28 | O17: 0 | P17: =IF(OR(N17="", O17=""), "", O17/N17) | W17: 45 | X17: 1 | Y17: =IF(OR(W17="", X17=""), "", X17/W17) | Z17: 35 | AA17: 2 | AB17: =IF(OR(Z17="", AA17=""), "", AA17/Z17) | AC17: 32 | AD17: 1 | AE17: =IF(OR(AC17="", AD17=""), "", AD17/AC17) | AF17: 28 | AG17: 0 | AH17: =IF(OR(AF17="", AG17=""), "", AG17/AF17)
C18: South | D18: April | E18: 42 | F18: 0 | G18: =IF(OR(E18="", F18=""), "", F18/E18) | H18: 31 | I18: 2 | J18: =IF(OR(H18="", I18=""), "", I18/H18) | K18: 33 | L18: 4 | M18: =IF(OR(K18="", L18=""), "", L18/K18) | N18: 32 | O18: 1 | P18: =IF(OR(N18="", O18=""), "", O18/N18) | W18: 42 | X18: 0 | Y18: =IF(OR(W18="", X18=""), "", X18/W18) | Z18: 31 | AA18: 2 | AB18: =IF(OR(Z18="", AA18=""), "", AA18/Z18) | AC18: 33 | AD18: 4 | AE18: =IF(OR(AC18="", AD18=""), "", AD18/AC18) | AF18: 32 | AG18: 1 | AH18: =IF(OR(AF18="", AG18=""), "", AG18/AF18)
C19: South | D19: Felina | E19: 45 | F19: 3 | G19: =IF(OR(E19="", F19=""), "", F19/E19) | H19: 48 | I19: 1 | J19: =IF(OR(H19="", I19=""), "", I19/H19) | K19: 46 | L19: 4 | M19: =IF(OR(K19="", L19=""), "", L19/K19) | N19: 47 | O19: 1 | P19: =IF(OR(N19="", O19=""), "", O19/N19) | W19: 45 | X19: 3 | Y19: =IF(OR(W19="", X19=""), "", X19/W19) | Z19: 48 | AA19: 1 | AB19: =IF(OR(Z19="", AA19=""), "", AA19/Z19) | AC19: 46 | AD19: 4 | AE19: =IF(OR(AC19="", AD19=""), "", AD19/AC19) | AF19: 47 | AG19: 1 | AH19: =IF(OR(AF19="", AG19=""), "", AG19/AF19)
C20: South | D20: Stephanie | E20: 47 | F20: 1 | G20: =IF(OR(E20="", F20=""), "", F20/E20) | H20: 53 | I20: 1 | J20: =IF(OR(H20="", I20=""), "", I20/H20) | K20: 48 | L20: 1 | M20: =IF(OR(K20="", L20=""), "", L20/K20) | N20: 51 | O20: 3 | P20: =IF(OR(N20="", O20=""), "", O20/N20) | W20: 47 | X20: 1 | Y20: =IF(OR(W20="", X20=""), "", X20/W20) | Z20: 53 | AA20: 1 | AB20: =IF(OR(Z20="", AA20=""), "", AA20/Z20) | AC20: 48 | AD20: 1 | AE20: =IF(OR(AC20="", AD20=""), "", AD20/AC20) | AF20: 51 | AG20: 3 | AH20: =IF(OR(AF20="", AG20=""), "", AG20/AF20)
C21: South | D21: Vincent | E21: 32 | F21: 3 | G21: =IF(OR(E21="", F21=""), "", F21/E21) | H21: 35 | I21: 3 | J21: =IF(OR(H21="", I21=""), "", I21/H21) | K21: 33 | L21: 1 | M21: =IF(OR(K21="", L21=""), "", L21/K21) | N21: 33 | O21: 0 | P21: =IF(OR(N21="", O21=""), "", O21/N21) | W21: 32 | X21: 3 | Y21: =IF(OR(W21="", X21=""), "", X21/W21) | Z21: 35 | AA21: 3 | AB21: =IF(OR(Z21="", AA21=""), "", AA21/Z21) | AC21: 33 | AD21: 1 | AE21: =IF(OR(AC21="", AD21=""), "", AD21/AC21) | AF21: 33 | AG21: 0 | AH21: =IF(OR(AF21="", AG21=""), "", AG21/AF21)
C22: South | D22: Janice | E22: 8 | F22: 2 | G22: =IF(OR(E22="", F22=""), "", F22/E22) | H22: 14 | I22: 0 | J22: =IF(OR(H22="", I22=""), "", I22/H22) | K22: 16 | L22: 0 | M22: =IF(OR(K22="", L22=""), "", L22/K22) | N22: 17 | O22: 0 | P22: =IF(OR(N22="", O22=""), "", O22/N22) | W22: 8 | X22: 2 | Y22: =IF(OR(W22="", X22=""), "", X22/W22) | Z22: 14 | AA22: 0 | AB22: =IF(OR(Z22="", AA22=""), "", AA22/Z22) | AC22: 16 | AD22: 0 | AE22: =IF(OR(AC22="", AD22=""), "", AD22/AC22) | AF22: 17 | AG22: 0 | AH22: =IF(OR(AF22="", AG22=""), "", AG22/AF22)
C23: South | D23: Raj | E23: 43 | F23: 1 | G23: =IF(OR(E23="", F23=""), "", F23/E23) | H23: 44 | I23: 1 | J23: =IF(OR(H23="", I23=""), "", I23/H23) | K23: 39 | L23: 2 | M23: =IF(OR(K23="", L23=""), "", L23/K23) | N23: 44 | O23: 1 | P23: =IF(OR(N23="", O23=""), "", O23/N23) | W23: 43 | X23: 1 | Y23: =IF(OR(W23="", X23=""), "", X23/W23) | Z23: 44 | AA23: 1 | AB23: =IF(OR(Z23="", AA23=""), "", AA23/Z23) | AC23: 39 | AD23: 2 | AE23: =IF(OR(AC23="", AD23=""), "", AD23/AC23) | AF23: 44 | AG23: 1 | AH23: =IF(OR(AF23="", AG23=""), "", AG23/AF23)
C24: South | D24: Shirley | G24: =IF(OR(E24="", F24=""), "", F24/E24) | H24: 23 | I24: 1 | J24: =IF(OR(H24="", I24=""), "", I24/H24) | K24: 36 | L24: 4 | M24: =IF(OR(K24="", L24=""), "", L24/K24) | N24: 46 | O24: 5 | P24: =IF(OR(N24="", O24=""), "", O24/N24) | S24: =IF(OR(Q24="", R24=""), "", R24/Q24) | V24: =IF(OR(T24="", U24=""), "", U24/T24) | Y24: =IF(OR(W24="", X24=""), "", X24/W24) | Z24: 23 | AA24: 1 | AB24: =IF(OR(Z24="", AA24=""), "", AA24/Z24) | AC24: 36 | AD24: 4 | AE24: =IF(OR(AC24="", AD24=""), "", AD24/AC24) | AF24: 46 | AG24: 5 | AH24: =IF(OR(AF24="", AG24=""), "", AG24/AF24) | AK24: =IF(OR(AI24="", AJ24=""), "", AJ24/AI24) | AN24: =IF(OR(AL24="", AM24=""), "", AM24/AL24)
J25: =IF(OR(H25="", I25=""), "", I25/H25) | M25: =IF(OR(K25="", L25=""), "", L25/K25) | P25: =IF(OR(N25="", O25=""), "", O25/N25) | S25: =IF(OR(Q25="", R25=""), "", R25/Q25) | V25: =IF(OR(T25="", U25=""), "", U25/T25)
J26: =IF(OR(H26="", I26=""), "", I26/H26) | M26: =IF(OR(K26="", L26=""), "", L26/K26) | P26: =IF(OR(N26="", O26=""), "", O26/N26) | S26: =IF(OR(Q26="", R26=""), "", R26/Q26) | V26: =IF(OR(T26="", U26=""), "", U26/T26)
J31: =IF(OR(H31="", I31=""), "", I31/H31) | M31: =IF(OR(K31="", L31=""), "", L31/K31) | P31: =IF(OR(N31="", O31=""), "", O31/N31) | S31: =IF(OR(Q31="", R31=""), "", R31/Q31) | V31: =IF(OR(T31="", U31=""), "", U31/T31)
J32: =IF(OR(H32="", I32=""), "", I32/H32) | M32: =IF(OR(K32="", L32=""), "", L32/K32) | P32: =IF(OR(N32="", O32=""), "", O32/N32) | S32: =IF(OR(Q32="", R32=""), "", R32/Q32) | V32: =IF(OR(T32="", U32=""), "", U32/T32)
J33: =IF(OR(H33="", I33=""), "", I33/H33) | M33: =IF(OR(K33="", L33=""), "", L33/K33) | P33: =IF(OR(N33="", O33=""), "", O33/N33) | S33: =IF(OR(Q33="", R33=""), "", R33/Q33) | V33: =IF(OR(T33="", U33=""), "", U33/T33)
J34: =IF(OR(H34="", I34=""), "", I34/H34) | M34: =IF(OR(K34="", L34=""), "", L34/K34) | P34: =IF(OR(N34="", O34=""), "", O34/N34) | S34: =IF(OR(Q34="", R34=""), "", R34/Q34) | V34: =IF(OR(T34="", U34=""), "", U34/T34)
J35: =IF(OR(H35="", I35=""), "", I35/H35) | M35: =IF(OR(K35="", L35=""), "", L35/K35) | P35: =IF(OR(N35="", O35=""), "", O35/N35) | S35: =IF(OR(Q35="", R35=""), "", R35/Q35) | V35: =IF(OR(T35="", U35=""), "", U35/T35)
J36: =IF(OR(H36="", I36=""), "", I36/H36) | M36: =IF(OR(K36="", L36=""), "", L36/K36) | P36: =IF(OR(N36="", O36=""), "", O36/N36) | S36: =IF(OR(Q36="", R36=""), "", R36/Q36) | V36: =IF(OR(T36="", U36=""), "", U36/T36)
J37: =IF(OR(H37="", I37=""), "", I37/H37) | M37: =IF(OR(K37="", L37=""), "", L37/K37) | P37: =IF(OR(N37="", O37=""), "", O37/N37) | S37: =IF(OR(Q37="", R37=""), "", R37/Q37) | V37: =IF(OR(T37="", U37=""), "", U37/T37)
J38: =IF(OR(H38="", I38=""), "", I38/H38) | M38: =IF(OR(K38="", L38=""), "", L38/K38) | P38: =IF(OR(N38="", O38=""), "", O38/N38) | S38: =IF(OR(Q38="", R38=""), "", R38/Q38) | V38: =IF(OR(T38="", U38=""), "", U38/T38)
J39: =IF(OR(H39="", I39=""), "", I39/H39) | M39: =IF(OR(K39="", L39=""), "", L39/K39) | P39: =IF(OR(N39="", O39=""), "", O39/N39) | S39: =IF(OR(Q39="", R39=""), "", R39/Q39) | V39: =IF(OR(T39="", U39=""), "", U39/T39)

Sheet Ceased reasons
A2: Therapist | B2: Month | C2: Client name | D2: Ceased Services/On Hold | E2: Client Type | F2: Reason for ceasing | I2: Therapists
A3: Alice | B3: 45839 | C3: Ursula Fredes-Ojeda | D3: Ceased Services | F3: Wants male physio in the area | I3: Alice
A4: Alice | B4: 45839 | C4: Olivia Baker | D4: Ceased Services | F4: On hold Feb 2025 - Remaining funds used for report instead of sessions - plan ending 5/6/25 Offboarded 16/7 - plan has ended and sc hasn’t gotten back to us. | I4: April
